Workbook

Sheet MODE D'EMPLOI
A1: Mode d'emploi
A3: FEUILLE RECAPITULATIF
A4: 1. Indiquer le nom de la classe
A5: 2. Compléter la liste des étudiants
A6: 3. Dans la feuille RECAPITULATIF, reporter le résultat obtenu par bloc issu du tableau "récapitulatif des résultats par bloc" de la feuille GROUPE 1
A8: FEUILLE GROUPE
A9: Dupliquer la feuille "GROUPE 1" en fonction du nombre de groupe
A10: Compléter la colonne "point" en utilisant la liste déroulante
A11: Note de groupe
A12: Note individuelle
A13: Note de groupe
A14: Compléter les notes de groupe pour l'etudiant 1
... A18: *Légende des parties SR
A19: Etudiants | B19: Parties
A20: Etudiant 1 | B20: Réseaux & Sécurité
A21: Etudiant 2 | B21: Administration des équipements utilisateurs
A22: Etudiant 3 | B22: Infrastructure informatique
A23: Etudiant 4 | B23: DevOps
A25: *Légende des parties DEV
A26: Etudiant 1
A27: Etudiant 2
A28: Etudiant 3

Sheet DATA & RECAP
B2: Classe: | C2: *Indiquer le nom de classe | H2: *Légende des parties | K2: Fonctionnement des grilles
B3: *A compléter afin de récupérer la liste des étudiants dans les grilles
B4: ETUDIANTS | E4: BLOCS
B5: Groupe Projet | C5: Nom | D5: Prénom | E5: BLOC 1 | F5: BLOC 2 | G5: BLOC 3

Sheet GROUPE 1
C3: NOM GROUPE PROJET : | E3: REF PEDA | K3: Note de groupe
K4: Note individuelle
C5: Etudiant 1 | D5: Etudiant 2 | E5: Etudiant 3 | F5: Etudiant 4 | G5: Etudiant 5
B6: Premier rendu : Rendez-vous de cadrage
K7: NOM | L7: Prénom | M7: BLOC 1 | N7: BLOC 2 | O7: BLOC 3
B8: Critères d'évaluation | C8: Points | J8: Etudiant 1 | L8: =_xlfn.XLOOKUP(K8,'DATA & RECAP'!$C$6:$C$32,'DATA & RECAP'!$D$6:$D$32,"Sélectionnez un nom") -> 0 | M8: =((((C19*$C$20)+(C35*$C$36))*2)*20)/100 -> 20 | N8: =((((C52*$C$53)+(C65*$C$66))*2)*20)/100 -> 20 | O8: =((C81*20)/50) -> 20
B9: Qualité des questions (logique, pertinence, clarté) | C9: 10 | D9: 10 | E9: 10 | F9: 10 | G9: 10 | J9: Etudiant 2 | L9: =_xlfn.XLOOKUP(K9,'DATA & RECAP'!$C$6:$C$32,'DATA & RECAP'!$D$6:$D$32,"Sélectionnez un nom") -> 0 | M9: =((((D19*$C$20)+(D35*$C$36))*2)*20)/100 -> 20 | N9: =((((D52*$C$53)+(D65*$C$66))*2)*20)/100 -> 20 | O9: =((D81*20)/50) -> 20
B10: Nombre de questions (minimum 3 par étudiant) | C10: 10 | D10: 10 | E10: 10 | F10: 10 | G10: 10 | J10: Etudiant 3 | L10: =_xlfn.XLOOKUP(K10,'DATA & RECAP'!$C$6:$C$32,'DATA & RECAP'!$D$6:$D$32,"Sélectionnez un nom") -> 0 | M10: =((((E19*$C$20)+(E35*$C$36))*2)*20)/100 -> 20 | N10: =((((E52*$C$53)+(E65*$C$66))*2)*20)/100 -> 20 | O10: =((E81*20)/50) -> 20
B11: Qualité d'animation | C11: 10 | D11: 10 | E11: 10 | F11: 10 | G11: 10 | J11: Etudiant 4 | L11: =_xlfn.XLOOKUP(K11,'DATA & RECAP'!$C$6:$C$32,'DATA & RECAP'!$D$6:$D$32,"Sélectionnez un nom") -> 0 | M11: =((((F19*$C$20)+(F35*$C$36))*2)*20)/100 -> 20 | N11: =((((F52*$C$53)+(F65*$C$66))*2)*20)/100 -> 20 | O11: =((F81*20)/50) -> 20
B12: Niveau de compréhension du sujet (démontré à travers les questions posées) | C12: 5 | D12: 5 | E12: 5 | F12: 5 | G12: 5 | J12: Etudiant 5 | L12: =_xlfn.XLOOKUP(K12,'DATA & RECAP'!$C$6:$C$32,'DATA & RECAP'!$D$6:$D$32,"Sélectionnez un nom") -> 0 | M12: =((((G19*$C$20)+(G35*$C$36))*2)*20)/100 -> 20 | N12: =((((G52*$C$53)+(G65*$C$66))*2)*20)/100 -> 20 | O12: =((G81*20)/50) -> 20
B13: Collaboration avec le "client" (qualité des échanges, réactivité) | C13: 5 | D13: 5 | E13: 5 | F13: 5 | G13: 5
B14: Clarté et organisation des documents (PDF, présentation, structure) | C14: 5 | D14: 5 | E14: 5 | F14: 5 | G14: 5
B15: Originalité et profondeur des questions posées (questions qui démontrent une réflexion approfondie sur le sujet) | C15: 3 | D15: 3 | E15: 3 | F15: 3 | G15: 3
B16: Qualité de la formulation et absence d'ambiguïté dans les questions | C16: 2 | D16: 2 | E16: 2 | F16: 2 | G16: 2
B18: Commentaire
B19: Total : 50 points | C19: =SUM(C9:C16) -> 50 | D19: =SUM(D9:D16) -> 50 | E19: =SUM(E9:E16) -> 50 | F19: =SUM(F9:F16) -> 50 | G19: =SUM(G9:G16) -> 50
B20: Rendu sur l’évaluation du bloc 1 « Piloter un Projet Informatique ». | C20: 0.2
B22: Deuxième rendu : Rendu de Cadrage
B24: Critères d'évaluation | C24: Points
B25: Pertinence et justification des choix techniques : Adéquation des technologies, outils ou frameworks retenus par rapport aux besoins du projet, accompagnée d’une justification claire. | C25: 10 | D25: 10 | E25: 10 | F25: 10 | G25: 10
B26: Clarté et cohérence du plan de projet : Structuration logique des étapes clés (conception, développement, tests, déploiement) et leur alignement avec les objectifs globaux. | C26: 10 | D26: 10 | E26: 10 | F26: 10 | G26: 10
B27: Précision et organisation du calendrier de planification : Identification des tâches, estimation réaliste des durées et clarté des dates de début et de fin. | C27: 10 | D27: 10 | E27: 10 | F27: 10 | G27: 10
B28: Qualité et pertinence des schémas techniques ou de planification : Utilisation efficace de diagrammes ou outils visuels (Gantt, PERT, UML, etc.) pour expliciter les étapes et les dépendances. | C28: 5 | D28: 5 | E28: 5 | F28: 5 | G28: 5
B29: Identification et gestion des dépendances entre tâches : Cohérence dans la gestion des relations entre les différentes étapes du projet et anticipation des impacts. | C29: 5 | D29: 5 | E29: 5 | F29: 5 | G29: 5
B30: Évaluation des risques et gestion anticipée : Identification des principaux risques et pertinence des stratégies proposées pour les atténuer. | C30: 5 | D30: 5 | E30: 5 | F30: 5 | G30: 5
B31: Inclusion et pertinence des jalons clés (milestones) : Définition claire des étapes de validation importantes dans la progression du projet. | C31: 3 | D31: 3 | E31: 3 | F31: 3 | G31: 3
B32: Estimation réaliste des ressources nécessaires : Cohérence des ressources (temps, personnes, matériel) avec les objectifs fixés. | C32: 2 | D32: 2 | E32: 2 | F32: 2 | G32: 2
B34: Commentaire
B35: Total : 50 points | C35: =SUM(C25:C32) -> 50 | D35: =SUM(D25:D32) -> 50 | E35: =SUM(E25:E32) -> 50 | F35: =SUM(F25:F32) -> 50 | G35: =SUM(G25:G32) -> 50
B36: Rendu sur l’évaluation du bloc 1 « Piloter un Projet Informatique ». | C36: 0.8
B38: Troisième rendu : Soutenance & démo du projet - MVP
B40: Critères d'évaluation | C40: Points
B41: Clarté de la présentation orale (Structure, fluidité, pertinence des informations, capacité à capter l’attention du jury.) | C41: 10 | D41: 10 | E41: 10 | F41: 10 | G41: 10
B42: Contexte et objectifs du projet (Présentation claire des besoins identifiés, compréhension globale du projet, et liens avec les attentes du client fictif.) | C42: 10 | D42: 10 | E42: 10 | F42: 10 | G42: 10
B43: Qualité de la démonstration du MVP (Fonctionnalités opérationnelles, pertinence par rapport aux besoins exprimés et valeur ajoutée.) | C43: 10 | D43: 10 | E43: 10 | F43: 10 | G43: 10
B44: Qualité du support (Esthétique, clarté des diapositives, cohérence visuelle, et adéquation au discours.) | C44: 5 | D44: 5 | E44: 5 | F44: 5 | G44: 5
B45: Pertinence des perspectives d’évolution (Propositions réalistes et stratégiques pour les prochaines phases du projet.) | C45: 5 | D45: 5 | E45: 5 | F45: 5 | G45: 5
B46: Originalité et innovation (Niveau d’innovation du MVP par rapport aux solutions existantes sur le marché ou aux attentes initiales.) | C46: 5 | D46: 5 | E46: 5 | F46: 5 | G46: 5
B47: Impact potentiel du MVP (Capacité à convaincre les utilisateurs finaux, satisfaction des besoins réels et apport d'une solution pérenne.) | C47: 5 | D47: 5 | E47: 5 | F47: 5 | G47: 5
B48: Aller plus loin que l'attendu (Ajustement de ±2 points : Intégration de fonctionnalités ou propositions supplémentaires dépassant les attentes initiales.) | C48: 0 | D48: 0 | E48: 0 | F48: 0 | G48: 0
...
